Workbook

Sheet Parametry
B2: 🏠 KALKULATOR KREDYTU HIPOTECZNEGO
B4: PARAMETRY KREDYTU
B5: Pozostała kwota do spłaty (saldo) | C5: 533693.01 | D5: Edytuj → aktualizuje harmonogram
B6: Liczba pozostałych rat | C6: 323 | D6: Edytuj → aktualizuje harmonogram
B7: Bieżąca rata miesięczna | C7: 3234.73 | D7: Edytuj → aktualizuje harmonogram
B8: Oprocentowanie I okres (%) | C8: 0.0579 | D8: np. 5,79% wpisz jako 0.0579
B9: Liczba rat w I okresie oprocentowania | C9: 58 | D9: Po tylu ratach zmiana stopy
B10: Oprocentowanie II okres (%) | C10: 0.06 | D10: Stopa po zmianie
B11: Dzień spłaty (dzień miesiąca) | C11: 19 | D11: 19 = 19. dzień miesiąca
B12: Rok startowy | C12: 2026 | D12: Rok pierwszej raty
B13: Miesiąc startowy (1-12) | C13: 7 | D13: 7 = lipiec
B15: JAK KORZYSTAĆ Z ARKUSZA
B16: 1. Sprawdź / edytuj parametry w żółtych polach powyżej.
B17: 2. Przejdź do arkusza 'Harmonogram'.
B18: 3. W kolumnie 'NADPŁATA (wpisz)' wpisz kwotę nadpłaty dla danego miesiąca.
B19: 4. Minimalna zalecana nadpłata = wysokość następnej raty (kolumna 'Sug. nadpłata').
B20: 5. Wszystkie pozostałe obliczenia aktualizują się automatycznie.
B21: 6. W arkuszu 'Podsumowanie' zobaczysz oszczędności i skrócenie okresu kredytu.

Sheet Harmonogram
A1: HARMONOGRAM SPŁATY KREDYTU HIPOTECZNEGO
A2: Lp. | B2: DATA SPŁATY | C2: NR RATY | D2: SALDO POCZĄTEK | E2: OPROCENT. | F2: ODSETKI | G2: RATA STANDARD. | H2: NADPŁATA (wpisz) | I2: SUG. NADPŁATA | J2: CAŁK. SPŁATA | K2: KAPITAŁ | L2: SALDO KONIEC | M2: POZ. RAT
A3: 1 | B3: =DATE(Parametry!$C$12+INT((Parametry!$C$13+1-2)/12),MOD(Parametry!$C$13+1-2,12)+1,Parametry!$C$11) | C3: 1 | D3: =Parametry!$C$5 | E3: =IF(C3<=Parametry!$C$9,Parametry!$C$8,Parametry!$C$10) | F3: =D3*E3/12 | G3: =Parametry!$C$7 | I3: =Parametry!$C$7 | J3: =G3+IF(ISNUMBER(H3),H3,0) | K3: =MAX(0,J3-F3) | L3: =MAX(0,D3-K3) | M3: =IF(L3<=0,0,MAX(0,ROUNDUP(-LN(1-L3*(E3/12)/Parametry!$C$7)/LN(1+E3/12),0)))
A4: 2 | B4: =DATE(Parametry!$C$12+INT((Parametry!$C$13+2-2)/12),MOD(Parametry!$C$13+2-2,12)+1,Parametry!$C$11) | C4: 2 | D4: =L3 | E4: =IF(C4<=Parametry!$C$9,Parametry!$C$8,Parametry!$C$10) | F4: =D4*E4/12 | G4: =Parametry!$C$7 | I4: =Parametry!$C$7 | J4: =G4+IF(ISNUMBER(H4),H4,0) | K4: =MAX(0,J4-F4) | L4: =MAX(0,D4-K4) | M4: =IF(L4<=0,0,MAX(0,ROUNDUP(-LN(1-L4*(E4/12)/Parametry!$C$7)/LN(1+E4/12),0)))
A5: 3 | B5: =DATE(Parametry!$C$12+INT((Parametry!$C$13+3-2)/12),MOD(Parametry!$C$13+3-2,12)+1,Parametry!$C$11) | C5: 3 | D5: =L4 | E5: =IF(C5<=Parametry!$C$9,Parametry!$C$8,Parametry!$C$10) | F5: =D5*E5/12 | G5: =Parametry!$C$7 | I5: =Parametry!$C$7 | J5: =G5+IF(ISNUMBER(H5),H5,0) | K5: =MAX(0,J5-F5) | L5: =MAX(0,D5-K5) | M5: =IF(L5<=0,0,MAX(0,ROUNDUP(-LN(1-L5*(E5/12)/Parametry!$C$7)/LN(1+E5/12),0)))
A6: 4 | B6: =DATE(Parametry!$C$12+INT((Parametry!$C$13+4-2)/12),MOD(Parametry!$C$13+4-2,12)+1,Parametry!$C$11) | C6: 4 | D6: =L5 | E6: =IF(C6<=Parametry!$C$9,Parametry!$C$8,Parametry!$C$10) | F6: =D6*E6/12 | G6: =Parametry!$C$7 | I6: =Parametry!$C$7 | J6: =G6+IF(ISNUMBER(H6),H6,0) | K6: =MAX(0,J6-F6) | L6: =MAX(0,D6-K6) | M6: =IF(L6<=0,0,MAX(0,ROUNDUP(-LN(1-L6*(E6/12)/Parametry!$C$7)/LN(1+E6/12),0)))
A7: 5 | B7: =DATE(Parametry!$C$12+INT((Parametry!$C$13+5-2)/12),MOD(Parametry!$C$13+5-2,12)+1,Parametry!$C$11) | C7: 5 | D7: =L6 | E7: =IF(C7<=Parametry!$C$9,Parametry!$C$8,Parametry!$C$10) | F7: =D7*E7/12 | G7: =Parametry!$C$7 | I7: =Parametry!$C$7 | J7: =G7+IF(ISNUMBER(H7),H7,0) | K7: =MAX(0,J7-F7) | L7: =MAX(0,D7-K7) | M7: =IF(L7<=0,0,MAX(0,ROUNDUP(-LN(1-L7*(E7/12)/Parametry!$C$7)/LN(1+E7/12),0)))
A8: 6 | B8: =DATE(Parametry!$C$12+INT((Parametry!$C$13+6-2)/12),MOD(Parametry!$C$13+6-2,12)+1,Parametry!$C$11) | C8: 6 | D8: =L7 | E8: =IF(C8<=Parametry!$C$9,Parametry!$C$8,Parametry!$C$10) | F8: =D8*E8/12 | G8: =Parametry!$C$7 | I8: =Parametry!$C$7 | J8: =G8+IF(ISNUMBER(H8),H8,0) | K8: =MAX(0,J8-F8) | L8: =MAX(0,D8-K8) | M8: =IF(L8<=0,0,MAX(0,ROUNDUP(-LN(1-L8*(E8/12)/Parametry!$C$7)/LN(1+E8/12),0)))
A9: 7 | B9: =DATE(Parametry!$C$12+INT((Parametry!$C$13+7-2)/12),MOD(Parametry!$C$13+7-2,12)+1,Parametry!$C$11) | C9: 7 | D9: =L8 | E9: =IF(C9<=Parametry!$C$9,Parametry!$C$8,Parametry!$C$10) | F9: =D9*E9/12 | G9: =Parametry!$C$7 | I9: =Parametry!$C$7 | J9: =G9+IF(ISNUMBER(H9),H9,0) | K9: =MAX(0,J9-F9) | L9: =MAX(0,D9-K9) | M9: =IF(L9<=0,0,MAX(0,ROUNDUP(-LN(1-L9*(E9/12)/Parametry!$C$7)/LN(1+E9/12),0)))
A10: 8 | B10: =DATE(Parametry!$C$12+INT((Parametry!$C$13+8-2)/12),MOD(Parametry!$C$13+8-2,12)+1,Parametry!$C$11) | C10: 8 | D10: =L9 | E10: =IF(C10<=Parametry!$C$9,Parametry!$C$8,Parametry!$C$10) | F10: =D10*E10/12 | G10: =Parametry!$C$7 | I10: =Parametry!$C$7 | J10: =G10+IF(ISNUMBER(H10),H10,0) | K10: =MAX(0,J10-F10) | L10: =MAX(0,D10-K10) | M10: =IF(L10<=0,0,MAX(0,ROUNDUP(-LN(1-L10*(E10/12)/Parametry!$C$7)/LN(1+E10/12),0)))
A11: 9 | B11: =DATE(Parametry!$C$12+INT((Parametry!$C$13+9-2)/12),MOD(Parametry!$C$13+9-2,12)+1,Parametry!$C$11) | C11: 9 | D11: =L10 | E11: =IF(C11<=Parametry!$C$9,Parametry!$C$8,Parametry!$C$10) | F11: =D11*E11/12 | G11: =Parametry!$C$7 | I11: =Parametry!$C$7 | J11: =G11+IF(ISNUMBER(H11),H11,0) | K11: =MAX(0,J11-F11) | L11: =MAX(0,D11-K11) | M11: =IF(L11<=0,0,MAX(0,ROUNDUP(-LN(1-L11*(E11/12)/Parametry!$C$7)/LN(1+E11/12),0)))
A12: 10 | B12: =DATE(Parametry!$C$12+INT((Parametry!$C$13+10-2)/12),MOD(Parametry!$C$13+10-2,12)+1,Parametry!$C$11) | C12: 10 | D12: =L11 | E12: =IF(C12<=Parametry!$C$9,Parametry!$C$8,Parametry!$C$10) | F12: =D12*E12/12 | G12: =Parametry!$C$7 | I12: =Parametry!$C$7 | J12: =G12+IF(ISNUMBER(H12),H12,0) | K12: =MAX(0,J12-F12) | L12: =MAX(0,D12-K12) | M12: =IF(L12<=0,0,MAX(0,ROUNDUP(-LN(1-L12*(E12/12)/Parametry!$C$7)/LN(1+E12/12),0)))
A13: 11 | B13: =DATE(Parametry!$C$12+INT((Parametry!$C$13+11-2)/12),MOD(Parametry!$C$13+11-2,12)+1,Parametry!$C$11) | C13: 11 | D13: =L12 | E13: =IF(C13<=Parametry!$C$9,Parametry!$C$8,Parametry!$C$10) | F13: =D13*E13/12 | G13: =Parametry!$C$7 | I13: =Parametry!$C$7 | J13: =G13+IF(ISNUMBER(H13),H13,0) | K13: =MAX(0,J13-F13) | L13: =MAX(0,D13-K13) | M13: =IF(L13<=0,0,MAX(0,ROUNDUP(-LN(1-L13*(E13/12)/Parametry!$C$7)/LN(1+E13/12),0)))
A14: 12 | B14: =DATE(Parametry!$C$12+INT((Parametry!$C$13+12-2)/12),MOD(Parametry!$C$13+12-2,12)+1,Parametry!$C$11) | C14: 12 | D14: =L13 | E14: =IF(C14<=Parametry!$C$9,Parametry!$C$8,Parametry!$C$10) | F14: =D14*E14/12 | G14: =Parametry!$C$7 | I14: =Parametry!$C$7 | J14: =G14+IF(ISNUMBER(H14),H14,0) | K14: =MAX(0,J14-F14) | L14: =MAX(0,D14-K14) | M14: =IF(L14<=0,0,MAX(0,ROUNDUP(-LN(1-L14*(E14/12)/Parametry!$C$7)/LN(1+E14/12),0)))
A15: 13 | B15: =DATE(Parametry!$C$12+INT((Parametry!$C$13+13-2)/12),MOD(Parametry!$C$13+13-2,12)+1,Parametry!$C$11) | C15: 13 | D15: =L14 | E15: =IF(C15<=Parametry!$C$9,Parametry!$C$8,Parametry!$C$10) | F15: =D15*E15/12 | G15: =Parametry!$C$7 | I15: =Parametry!$C$7 | J15: =G15+IF(ISNUMBER(H15),H15,0) | K15: =MAX(0,J15-F15) | L15: =MAX(0,D15-K15) | M15: =IF(L15<=0,0,MAX(0,ROUNDUP(-LN(1-L15*(E15/12)/Parametry!$C$7)/LN(1+E15/12),0)))
A16: 14 | B16: =DATE(Parametry!$C$12+INT((Parametry!$C$13+14-2)/12),MOD(Parametry!$C$13+14-2,12)+1,Parametry!$C$11) | C16: 14 | D16: =L15 | E16: =IF(C16<=Parametry!$C$9,Parametry!$C$8,Parametry!$C$10) | F16: =D16*E16/12 | G16: =Parametry!$C$7 | I16: =Parametry!$C$7 | J16: =G16+IF(ISNUMBER(H16),H16,0) | K16: =MAX(0,J16-F16) | L16: =MAX(0,D16-K16) | M16: =IF(L16<=0,0,MAX(0,ROUNDUP(-LN(1-L16*(E16/12)/Parametry!$C$7)/LN(1+E16/12),0)))
A17: 15 | B17: =DATE(Parametry!$C$12+INT((Parametry!$C$13+15-2)/12),MOD(Parametry!$C$13+15-2,12)+1,Parametry!$C$11) | C17: 15 | D17: =L16 | E17: =IF(C17<=Parametry!$C$9,Parametry!$C$8,Parametry!$C$10) | F17: =D17*E17/12 | G17: =Parametry!$C$7 | I17: =Parametry!$C$7 | J17: =G17+IF(ISNUMBER(H17),H17,0) | K17: =MAX(0,J17-F17) | L17: =MAX(0,D17-K17) | M17: =IF(L17<=0,0,MAX(0,ROUNDUP(-LN(1-L17*(E17/12)/Parametry!$C$7)/LN(1+E17/12),0)))
A18: 16 | B18: =DATE(Parametry!$C$12+INT((Parametry!$C$13+16-2)/12),MOD(Parametry!$C$13+16-2,12)+1,Parametry!$C$11) | C18: 16 | D18: =L17 | E18: =IF(C18<=Parametry!$C$9,Parametry!$C$8,Parametry!$C$10) | F18: =D18*E18/12 | G18: =Parametry!$C$7 | I18: =Parametry!$C$7 | J18: =G18+IF(ISNUMBER(H18),H18,0) | K18: =MAX(0,J18-F18) | L18: =MAX(0,D18-K18) | M18: =IF(L18<=0,0,MAX(0,ROUNDUP(-LN(1-L18*(E18/12)/Parametry!$C$7)/LN(1+E18/12),0)))
A19: 17 | B19: =DATE(Parametry!$C$12+INT((Parametry!$C$13+17-2)/12),MOD(Parametry!$C$13+17-2,12)+1,Parametry!$C$11) | C19: 17 | D19: =L18 | E19: =IF(C19<=Parametry!$C$9,Parametry!$C$8,Parametry!$C$10) | F19: =D19*E19/12 | G19: =Parametry!$C$7 | I19: =Parametry!$C$7 | J19: =G19+IF(ISNUMBER(H19),H19,0) | K19: =MAX(0,J19-F19) | L19: =MAX(0,D19-K19) | M19: =IF(L19<=0,0,MAX(0,ROUNDUP(-LN(1-L19*(E19/12)/Parametry!$C$7)/LN(1+E19/12),0)))
A20: 18 | B20: =DATE(Parametry!$C$12+INT((Parametry!$C$13+18-2)/12),MOD(Parametry!$C$13+18-2,12)+1,Parametry!$C$11) | C20: 18 | D20: =L19 | E20: =IF(C20<=Parametry!$C$9,Parametry!$C$8,Parametry!$C$10) | F20: =D20*E20/12 | G20: =Parametry!$C$7 | I20: =Parametry!$C$7 | J20: =G20+IF(ISNUMBER(H20),H20,0) | K20: =MAX(0,J20-F20) | L20: =MAX(0,D20-K20) | M20: =IF(L20<=0,0,MAX(0,ROUNDUP(-LN(1-L20*(E20/12)/Parametry!$C$7)/LN(1+E20/12),0)))
A21: 19 | B21: =DATE(Parametry!$C$12+INT((Parametry!$C$13+19-2)/12),MOD(Parametry!$C$13+19-2,12)+1,Parametry!$C$11) | C21: 19 | D21: =L20 | E21: =IF(C21<=Parametry!$C$9,Parametry!$C$8,Parametry!$C$10) | F21: =D21*E21/12 | G21: =Parametry!$C$7 | I21: =Parametry!$C$7 | J21: =G21+IF(ISNUMBER(H21),H21,0) | K21: =MAX(0,J21-F21) | L21: =MAX(0,D21-K21) | M21: =IF(L21<=0,0,MAX(0,ROUNDUP(-LN(1-L21*(E21/12)/Parametry!$C$7)/LN(1+E21/12),0)))
A22: 20 | B22: =DATE(Parametry!$C$12+INT((Parametry!$C$13+20-2)/12),MOD(Parametry!$C$13+20-2,12)+1,Parametry!$C$11) | C22: 20 | D22: =L21 | E22: =IF(C22<=Parametry!$C$9,Parametry!$C$8,Parametry!$C$10) | F22: =D22*E22/12 | G22: =Parametry!$C$7 | I22: =Parametry!$C$7 | J22: =G22+IF(ISNUMBER(H22),H22,0) | K22: =MAX(0,J22-F22) | L22: =MAX(0,D22-K22) | M22: =IF(L22<=0,0,MAX(0,ROUNDUP(-LN(1-L22*(E22/12)/Parametry!$C$7)/LN(1+E22/12),0)))
A23: 21 | B23: =DATE(Parametry!$C$12+INT((Parametry!$C$13+21-2)/12),MOD(Parametry!$C$13+21-2,12)+1,Parametry!$C$11) | C23: 21 | D23: =L22 | E23: =IF(C23<=Parametry!$C$9,Parametry!$C$8,Parametry!$C$10) | F23: =D23*E23/12 | G23: =Parametry!$C$7 | I23: =Parametry!$C$7 | J23: =G23+IF(ISNUMBER(H23),H23,0) | K23: =MAX(0,J23-F23) | L23: =MAX(0,D23-K23) | M23: =IF(L23<=0,0,MAX(0,ROUNDUP(-LN(1-L23*(E23/12)/Parametry!$C$7)/LN(1+E23/12),0)))
A24: 22 | B24: =DATE(Parametry!$C$12+INT((Parametry!$C$13+22-2)/12),MOD(Parametry!$C$13+22-2,12)+1,Parametry!$C$11) | C24: 22 | D24: =L23 | E24: =IF(C24<=Parametry!$C$9,Parametry!$C$8,Parametry!$C$10) | F24: =D24*E24/12 | G24: =Parametry!$C$7 | I24: =Parametry!$C$7 | J24: =G24+IF(ISNUMBER(H24),H24,0) | K24: =MAX(0,J24-F24) | L24: =MAX(0,D24-K24) | M24: =IF(L24<=0,0,MAX(0,ROUNDUP(-LN(1-L24*(E24/12)/Parametry!$C$7)/LN(1+E24/12),0)))
A25: 23 | B25: =DATE(Parametry!$C$12+INT((Parametry!$C$13+23-2)/12),MOD(Parametry!$C$13+23-2,12)+1,Parametry!$C$11) | C25: 23 | D25: =L24 | E25: =IF(C25<=Parametry!$C$9,Parametry!$C$8,Parametry!$C$10) | F25: =D25*E25/12 | G25: =Parametry!$C$7 | I25: =Parametry!$C$7 | J25: =G25+IF(ISNUMBER(H25),H25,0) | K25: =MAX(0,J25-F25) | L25: =MAX(0,D25-K25) | M25: =IF(L25<=0,0,MAX(0,ROUNDUP(-LN(1-L25*(E25/12)/Parametry!$C$7)/LN(1+E25/12),0)))
A26: 24 | B26: =DATE(Parametry!$C$12+INT((Parametry!$C$13+24-2)/12),MOD(Parametry!$C$13+24-2,12)+1,Parametry!$C$11) | C26: 24 | D26: =L25 | E26: =IF(C26<=Parametry!$C$9,Parametry!$C$8,Parametry!$C$10) | F26: =D26*E26/12 | G26: =Parametry!$C$7 | I26: =Parametry!$C$7 | J26: =G26+IF(ISNUMBER(H26),H26,0) | K26: =MAX(0,J26-F26) | L26: =MAX(0,D26-K26) | M26: =IF(L26<=0,0,MAX(0,ROUNDUP(-LN(1-L26*(E26/12)/Parametry!$C$7)/LN(1+E26/12),0)))
A27: 25 | B27: =DATE(Parametry!$C$12+INT((Parametry!$C$13+25-2)/12),MOD(Parametry!$C$13+25-2,12)+1,Parametry!$C$11) | C27: 25 | D27: =L26 | E27: =IF(C27<=Parametry!$C$9,Parametry!$C$8,Parametry!$C$10) | F27: =D27*E27/12 | G27: =Parametry!$C$7 | I27: =Parametry!$C$7 | J27: =G27+IF(ISNUMBER(H27),H27,0) | K27: =MAX(0,J27-F27) | L27: =MAX(0,D27-K27) | M27: =IF(L27<=0,0,MAX(0,ROUNDUP(-LN(1-L27*(E27/12)/Parametry!$C$7)/LN(1+E27/12),0)))
A28: 26 | B28: =DATE(Parametry!$C$12+INT((Parametry!$C$13+26-2)/12),MOD(Parametry!$C$13+26-2,12)+1,Parametry!$C$11) | C28: 26 | D28: =L27 | E28: =IF(C28<=Parametry!$C$9,Parametry!$C$8,Parametry!$C$10) | F28: =D28*E28/12 | G28: =Parametry!$C$7 | I28: =Parametry!$C$7 | J28: =G28+IF(ISNUMBER(H28),H28,0) | K28: =MAX(0,J28-F28) | L28: =MAX(0,D28-K28) | M28: =IF(L28<=0,0,MAX(0,ROUNDUP(-LN(1-L28*(E28/12)/Parametry!$C$7)/LN(1+E28/12),0)))
A29: 27 | B29: =DATE(Parametry!$C$12+INT((Parametry!$C$13+27-2)/12),MOD(Parametry!$C$13+27-2,12)+1,Parametry!$C$11) | C29: 27 | D29: =L28 | E29: =IF(C29<=Parametry!$C$9,Parametry!$C$8,Parametry!$C$10) | F29: =D29*E29/12 | G29: =Parametry!$C$7 | I29: =Parametry!$C$7 | J29: =G29+IF(ISNUMBER(H29),H29,0) | K29: =MAX(0,J29-F29) | L29: =MAX(0,D29-K29) | M29: =IF(L29<=0,0,MAX(0,ROUNDUP(-LN(1-L29*(E29/12)/Parametry!$C$7)/LN(1+E29/12),0)))
A30: 28 | B30: =DATE(Parametry!$C$12+INT((Parametry!$C$13+28-2)/12),MOD(Parametry!$C$13+28-2,12)+1,Parametry!$C$11) | C30: 28 | D30: =L29 | E30: =IF(C30<=Parametry!$C$9,Parametry!$C$8,Parametry!$C$10) | F30: =D30*E30/12 | G30: =Parametry!$C$7 | I30: =Parametry!$C$7 | J30: =G30+IF(ISNUMBER(H30),H30,0) | K30: =MAX(0,J30-F30) | L30: =MAX(0,D30-K30) | M30: =IF(L30<=0,0,MAX(0,ROUNDUP(-LN(1-L30*(E30/12)/Parametry!$C$7)/LN(1+E30/12),0)))
A31: 29 | B31: =DATE(Parametry!$C$12+INT((Parametry!$C$13+29-2)/12),MOD(Parametry!$C$13+29-2,12)+1,Parametry!$C$11) | C31: 29 | D31: =L30 | E31: =IF(C31<=Parametry!$C$9,Parametry!$C$8,Parametry!$C$10) | F31: =D31*E31/12 | G31: =Parametry!$C$7 | I31: =Parametry!$C$7 | J31: =G31+IF(ISNUMBER(H31),H31,0) | K31: =MAX(0,J31-F31) | L31: =MAX(0,D31-K31) | M31: =IF(L31<=0,0,MAX(0,ROUNDUP(-LN(1-L31*(E31/12)/Parametry!$C$7)/LN(1+E31/12),0)))
A32: 30 | B32: =DATE(Parametry!$C$12+INT((Parametry!$C$13+30-2)/12),MOD(Parametry!$C$13+30-2,12)+1,Parametry!$C$11) | C32: 30 | D32: =L31 | E32: =IF(C32<=Parametry!$C$9,Parametry!$C$8,Parametry!$C$10) | F32: =D32*E32/12 | G32: =Parametry!$C$7 | I32: =Parametry!$C$7 | J32: =G32+IF(ISNUMBER(H32),H32,0) | K32: =MAX(0,J32-F32) | L32: =MAX(0,D32-K32) | M32: =IF(L32<=0,0,MAX(0,ROUNDUP(-LN(1-L32*(E32/12)/Parametry!$C$7)/LN(1+E32/12),0)))
A33: 31 | B33: =DATE(Parametry!$C$12+INT((Parametry!$C$13+31-2)/12),MOD(Parametry!$C$13+31-2,12)+1,Parametry!$C$11) | C33: 31 | D33: =L32 | E33: =IF(C33<=Parametry!$C$9,Parametry!$C$8,Parametry!$C$10) | F33: =D33*E33/12 | G33: =Parametry!$C$7 | I33: =Parametry!$C$7 | J33: =G33+IF(ISNUMBER(H33),H33,0) | K33: =MAX(0,J33-F33) | L33: =MAX(0,D33-K33) | M33: =IF(L33<=0,0,MAX(0,ROUNDUP(-LN(1-L33*(E33/12)/Parametry!$C$7)/LN(1+E33/12),0)))
A34: 32 | B34: =DATE(Parametry!$C$12+INT((Parametry!$C$13+32-2)/12),MOD(Parametry!$C$13+32-2,12)+1,Parametry!$C$11) | C34: 32 | D34: =L33 | E34: =IF(C34<=Parametry!$C$9,Parametry!$C$8,Parametry!$C$10) | F34: =D34*E34/12 | G34: =Parametry!$C$7 | I34: =Parametry!$C$7 | J34: =G34+IF(ISNUMBER(H34),H34,0) | K34: =MAX(0,J34-F34) | L34: =MAX(0,D34-K34) | M34: =IF(L34<=0,0,MAX(0,ROUNDUP(-LN(1-L34*(E34/12)/Parametry!$C$7)/LN(1+E34/12),0)))
A35: 33 | B35: =DATE(Parametry!$C$12+INT((Parametry!$C$13+33-2)/12),MOD(Parametry!$C$13+33-2,12)+1,Parametry!$C$11) | C35: 33 | D35: =L34 | E35: =IF(C35<=Parametry!$C$9,Parametry!$C$8,Parametry!$C$10) | F35: =D35*E35/12 | G35: =Parametry!$C$7 | I35: =Parametry!$C$7 | J35: =G35+IF(ISNUMBER(H35),H35,0) | K35: =MAX(0,J35-F35) | L35: =MAX(0,D35-K35) | M35: =IF(L35<=0,0,MAX(0,ROUNDUP(-LN(1-L35*(E35/12)/Parametry!$C$7)/LN(1+E35/12),0)))
A36: 34 | B36: =DATE(Parametry!$C$12+INT((Parametry!$C$13+34-2)/12),MOD(Parametry!$C$13+34-2,12)+1,Parametry!$C$11) | C36: 34 | D36: =L35 | E36: =IF(C36<=Parametry!$C$9,Parametry!$C$8,Parametry!$C$10) | F36: =D36*E36/12 | G36: =Parametry!$C$7 | I36: =Parametry!$C$7 | J36: =G36+IF(ISNUMBER(H36),H36,0) | K36: =MAX(0,J36-F36) | L36: =MAX(0,D36-K36) | M36: =IF(L36<=0,0,MAX(0,ROUNDUP(-LN(1-L36*(E36/12)/Parametry!$C$7)/LN(1+E36/12),0)))
A37: 35 | B37: =DATE(Parametry!$C$12+INT((Parametry!$C$13+35-2)/12),MOD(Parametry!$C$13+35-2,12)+1,Parametry!$C$11) | C37: 35 | D37: =L36 | E37: =IF(C37<=Parametry!$C$9,Parametry!$C$8,Parametry!$C$10) | F37: =D37*E37/12 | G37: =Parametry!$C$7 | I37: =Parametry!$C$7 | J37: =G37+IF(ISNUMBER(H37),H37,0) | K37: =MAX(0,J37-F37) | L37: =MAX(0,D37-K37) | M37: =IF(L37<=0,0,MAX(0,ROUNDUP(-LN(1-L37*(E37/12)/Parametry!$C$7)/LN(1+E37/12),0)))
A38: 36 | B38: =DATE(Parametry!$C$12+INT((Parametry!$C$13+36-2)/12),MOD(Parametry!$C$13+36-2,12)+1,Parametry!$C$11) | C38: 36 | D38: =L37 | E38: =IF(C38<=Parametry!$C$9,Parametry!$C$8,Parametry!$C$10) | F38: =D38*E38/12 | G38: =Parametry!$C$7 | I38: =Parametry!$C$7 | J38: =G38+IF(ISNUMBER(H38),H38,0) | K38: =MAX(0,J38-F38) | L38: =MAX(0,D38-K38) | M38: =IF(L38<=0,0,MAX(0,ROUNDUP(-LN(1-L38*(E38/12)/Parametry!$C$7)/LN(1+E38/12),0)))
A39: 37 | B39: =DATE(Parametry!$C$12+INT((Parametry!$C$13+37-2)/12),MOD(Parametry!$C$13+37-2,12)+1,Parametry!$C$11) | C39: 37 | D39: =L38 | E39: =IF(C39<=Parametry!$C$9,Parametry!$C$8,Parametry!$C$10) | F39: =D39*E39/12 | G39: =Parametry!$C$7 | I39: =Parametry!$C$7 | J39: =G39+IF(ISNUMBER(H39),H39,0) | K39: =MAX(0,J39-F39) | L39: =MAX(0,D39-K39) | M39: =IF(L39<=0,0,MAX(0,ROUNDUP(-LN(1-L39*(E39/12)/Parametry!$C$7)/LN(1+E39/12),0)))
A40: 38 | B40: =DATE(Parametry!$C$12+INT((Parametry!$C$13+38-2)/12),MOD(Parametry!$C$13+38-2,12)+1,Parametry!$C$11) | C40: 38 | D40: =L39 | E40: =IF(C40<=Parametry!$C$9,Parametry!$C$8,Parametry!$C$10) | F40: =D40*E40/12 | G40: =Parametry!$C$7 | I40: =Parametry!$C$7 | J40: =G40+IF(ISNUMBER(H40),H40,0) | K40: =MAX(0,J40-F40) | L40: =MAX(0,D40-K40) | M40: =IF(L40<=0,0,MAX(0,ROUNDUP(-LN(1-L40*(E40/12)/Parametry!$C$7)/LN(1+E40/12),0)))
...

Sheet Podsumowanie
B2: PODSUMOWANIE SPŁATY KREDYTU
B4: BEZ NADPŁAT
B5: Suma odsetek z harmonogramu (ogółem) | C5: =SUMPRODUCT(Harmonogram!F3:F327)
B6: Całkowita kwota spłat (kapitał + odsetki + nadpłaty) | C6: =SUMPRODUCT(Harmonogram!J3:J327)
B7: Suma nadpłat wpisanych | C7: =SUMIF(Harmonogram!H3:H327,">"&0,Harmonogram!H3:H327)
B9: OSZCZĘDNOŚCI DZIĘKI NADPŁATOM
B10: Ostatnia rata z nadpłatami (numer raty w harmonogramie) | C10: =IFERROR(MATCH(TRUE,INDEX(Harmonogram!L3:L327<=0,),0),Parametry!$C$6) | D10: * Jeśli brak nadpłat, pokazuje ostatnią ratę z tabeli
B11: Liczba rat bez nadpłat (parametr) | C11: =Parametry!$C$6
B12: Liczba rat skrócona dzięki nadpłatom | C12: =MAX(0,Parametry!$C$6-C10)
B13: Data ostatecznej spłaty (z nadpłatami) | C13: =DATE(Parametry!$C$12+INT((Parametry!$C$13+C10-2)/12),MOD(Parametry!$C$13+C10-2,12)+1,Parametry!$C$11)
B14: Data ostatecznej spłaty (bez nadpłat) | C14: =DATE(Parametry!$C$12+INT((Parametry!$C$13+Parametry!$C$6-2)/12),MOD(Parametry!$C$13+Parametry!$C$6-2,12)+1,Parametry!$C$11)
B16: SZACOWANE ODSETKI – PORÓWNANIE
B17: Teoretyczne odsetki bez nadpłat (annuity) | C17: =Parametry!$C$7*Parametry!$C$6-Parametry!$C$5
B18: Rzeczywiste odsetki z harmonogramu | C18: =Podsumowanie!C5
B19: Oszczędność na odsetkach (szacunek) | C19: =MAX(0,C17-C5)
